Workbook

Sheet Main BUS
A1: Main Bus | B1: V3.0 | C1: Total Loading Race: | D1: =SUMIF(Main_Bus[In Use Race], "=TRUE", Main_Bus[Loading (%)])/100 -> 0.29617436 | F1: Data Logger Max Rate: | G1: 0.52 | I1: Convert to dbc: | J1: 10 - Software
C2: Total Loading Charge: | D2: =SUMIF(Main_Bus[In Use Charge], "=TRUE", Main_Bus[Loading (%)])/100 -> 0.18062769 | F2: Telemetry Max Rate: | G2: 0.74
A4: Documented? | B4: ID | C4: Name | D4: Rate (ms) | E4: Length (Bytes) | F4: Loading (%) | G4: Sender | H4: Reciever | I4: In Use Race | J4: In Use Charge | K4: Description
A5: =COUNTIF('Main BUS Message'!$A$1:$A$10091,B5) -> 1 | B5: 0x024 | C5: SetCurrent | D5: 100 | E5: 2 | F5: =IF((I5),(E5+3)*(1000/D5)/1000,0) -> 0 | G5: Debug | H5: Inverter | I5: FALSE | J5: FALSE | K5: Set AC Current - Current (2-byte)
A6: =COUNTIF('Main BUS Message'!$A$1:$A$10091,B6) -> 1 | B6: 0x044 | C6: SetBreakCurrent | D6: 100 | E6: 2 | F6: =IF((I6),(E6+3)*(1000/D6)/1000,0) -> 0 | G6: Debug | H6: Inverter | I6: FALSE | J6: FALSE | K6: Set AC Break Current - Current (2-byte, x10)
A7: =COUNTIF('Main BUS Message'!$A$1:$A$10091,B7) -> 1 | B7: 0x064 | C7: SetERPM | D7: 100 | E7: 4 | F7: =IF((I7),(E7+3)*(1000/D7)/1000,0) -> 0 | G7: Debug | H7: Inverter | I7: FALSE | J7: FALSE | K7: Set ERPM - ERPM (4-byte)
A8: =COUNTIF('Main BUS Message'!$A$1:$A$10091,B8) -> 1 | B8: 0x084 | C8: SetPostion | D8: 100 | E8: 2 | F8: =IF((I8),(E8+3)*(1000/D8)/1000,0) -> 0 | G8: Debug | H8: Inverter | I8: FALSE | J8: FALSE | K8: Set Position (hold motor at angle in degrees if encoder exists) - Angle (2-byte, x10)
A9: =COUNTIF('Main BUS Message'!$A$1:$A$10091,B9) -> 1 | B9: 0x0C4 | C9: SetRelativeBreak | D9: 100 | E9: 2 | F9: =IF((I9),(E9+3)*(1000/D9)/1000,0) -> 0 | G9: Debug | H9: Inverter | I9: FALSE | J9: FALSE | K9: Set relative break current
A10: =COUNTIF('Main BUS Message'!$A$1:$A$10091,B10) -> 1 | B10: 0x0E4 | C10: SetDigOut | D10: 100 | E10: 8 | F10: =IF((I10),(E10+3)*(1000/D10)/1000,0) -> 0 | G10: Debug | H10: Inverter | I10: FALSE | J10: FALSE | K10: Set digital output
A11: =COUNTIF('Main BUS Message'!$A$1:$A$10091,B11) -> 1 | B11: 0x104 | C11: SetCurrentMaxAC | D11: 100 | E11: 8 | F11: =IF((I11),(E11+3)*(1000/D11)/1000,0) -> 0 | G11: Debug | H11: Inverter | I11: FALSE | J11: FALSE | K11: Set max AC current
A12: =COUNTIF('Main BUS Message'!$A$1:$A$10091,B12) -> 1 | B12: 0x124 | C12: SetBreakCurrentMax | D12: 100 | E12: 2 | F12: =IF((I12),(E12+3)*(1000/D12)/1000,0) -> 0 | G12: Debug | H12: Inverter | I12: FALSE | J12: FALSE | K12: Set max AC break current
A13: =COUNTIF('Main BUS Message'!$A$1:$A$10091,B13) -> 1 | B13: 0x144 | C13: SetCurrentMaxDC | D13: 100 | E13: 2 | F13: =IF((I13),(E13+3)*(1000/D13)/1000,0) -> 0 | G13: Debug | H13: Inverter | I13: FALSE | J13: FALSE | K13: Set max DC current
A14: =COUNTIF('Main BUS Message'!$A$1:$A$10091,B14) -> 1 | B14: 0x164 | C14: SetBreakCurrentMaxDC | D14: 100 | E14: 2 | F14: =IF((I14),(E14+3)*(1000/D14)/1000,0) -> 0 | G14: Debug | H14: Inverter | I14: FALSE | J14: FALSE | K14: Set max DC break current
A15: =COUNTIF('Main BUS Message'!$A$1:$A$10091,B15) -> 1 | B15: 0x016 | C15: StatusAPPS | D15: 1000 | E15: 8 | F15: =IF((I15),(E15+3)*(1000/D15)/1000,0) -> 0.011 | G15: APPS | H15: Logger | I15: TRUE | J15: FALSE | K15: MCU Status Message
A16: =COUNTIF('Main BUS Message'!$A$1:$A$10091,B16) -> 1 | B16: 0x081 | C16: StatusAPPSSensor | D16: 1000 | E16: 1 | F16: =IF((I16),(E16+3)*(1000/D16)/1000,0) -> 0.004 | G16: APPS | H16: Screen | I16: TRUE | J16: FALSE | K16: APPS Sensor Status
... A26: =COUNTIF('Main BUS Message'!$A$1:$A$10091,B26) -> 1 | B26: 0x6B5 | C26: CellVoltages3 | D26: 8 | E26: 8 | F26: =IF((I26),(E26+3)*(1000/D26)/1000,0) -> 1.375 | G26: BMS | H26: Logger | I26: TRUE | J26: TRUE | K26: ID Reserved for BMS
A27: =COUNTIF('Main BUS Message'!$A$1:$A$10091,B27) -> 0 | B27: 0x6B6 | C27: BMSSpare1 | F27: =IF((I27),(E27+3)*(1000/D27)/1000,0) -> 0 | G27: BMS | H27: - | I27: FALSE | J27: FALSE | K27: ID Reserved for BMS
A28: =COUNTIF('Main BUS Message'!$A$1:$A$10091,B28) -> 0 | B28: 0x6B7 | C28: BMSSpare2 | F28: =IF((I28),(E28+3)*(1000/D28)/1000,0) -> 0 | G28: BMS | H28: - | I28: FALSE | J28: FALSE | K28: ID Reserved for BMS
A29: =COUNTIF('Main BUS Message'!$A$1:$A$10091,B29) -> 0 | B29: 0x6B8 | C29: BMSSpare3 | F29: =IF((I29),(E29+3)*(1000/D29)/1000,0) -> 0 | G29: BMS | H29: - | I29: FALSE | J29: FALSE | K29: ID Reserved for BMS
A30: =COUNTIF('Main BUS Message'!$A$1:$A$10091,B30) -> 0 | B30: 0x6B9 | C30: BMSSpare4 | F30: =IF((I30),(E30+3)*(1000/D30)/1000,0) -> 0 | G30: BMS | H30: - | I30: FALSE | J30: FALSE | K30: ID Reserved for BMS
A31: =COUNTIF('Main BUS Message'!$A$1:$A$10091,B31) -> 0 | B31: 0x6BA | C31: BMSSpare5 | F31: =IF((I31),(E31+3)*(1000/D31)/1000,0) -> 0 | G31: BMS | H31: - | I31: FALSE | J31: FALSE | K31: ID Reserved for BMS
A32: =COUNTIF('Main BUS Message'!$A$1:$A$10091,B32) -> 0 | B32: 0x6BB | C32: BMSSpare6 | F32: =IF((I32),(E32+3)*(1000/D32)/1000,0) -> 0 | G32: BMS | H32: - | I32: FALSE | J32: FALSE | K32: ID Reserved for BMS
A33: =COUNTIF('Main BUS Message'!$A$1:$A$10091,B33) -> 0 | B33: 0x6BC | C33: BMSSpare7 | F33: =IF((I33),(E33+3)*(1000/D33)/1000,0) -> 0 | G33: BMS | H33: - | I33: FALSE | J33: FALSE | K33: ID Reserved for BMS
A34: =COUNTIF('Main BUS Message'!$A$1:$A$10091,B34) -> 0 | B34: 0x6BD | C34: BMSSpare8 | F34: =IF((I34),(E34+3)*(1000/D34)/1000,0) -> 0 | G34: BMS | H34: - | I34: FALSE | J34: FALSE | K34: ID Reserved for BMS
A35: =COUNTIF('Main BUS Message'!$A$1:$A$10091,B35) -> 0 | B35: 0x6BE | C35: BMSSpare9 | F35: =IF((I35),(E35+3)*(1000/D35)/1000,0) -> 0 | G35: BMS | H35: - | I35: FALSE | J35: FALSE | K35: ID Reserved for BMS
A36: =COUNTIF('Main BUS Message'!$A$1:$A$10091,B36) -> 0 | B36: 0x6BF | C36: BMSSpare10 | F36: =IF((I36),(E36+3)*(1000/D36)/1000,0) -> 0 | G36: BMS | H36: - | I36: FALSE | J36: FALSE | K36: ID Reserved for BMS
A37: =COUNTIF('Main BUS Message'!$A$1:$A$10091,B37) -> 0 | B37: 0x6C0 | C37: BMSSpare11 | F37: =IF((I37),(E37+3)*(1000/D37)/1000,0) -> 0 | G37: BMS | H37: - | I37: FALSE | J37: FALSE | K37: ID Reserved for BMS
A38: =COUNTIF('Main BUS Message'!$A$1:$A$10091,B38) -> 0 | B38: 0x6C1 | C38: BMSSpare12 | F38: =IF((I38),(E38+3)*(1000/D38)/1000,0) -> 0 | G38: BMS | H38: - | I38: FALSE | J38: FALSE | K38: ID Reserved for BMS
A39: =COUNTIF('Main BUS Message'!$A$1:$A$10091,B39) -> 1 | B39: 0x010 | C39: ESPControl | D39: 100 | E39: 2 | F39: =IF((I39),(E39+3)*(1000/D39)/1000,0) -> 0.05 | G39: Dash | H39: Logger/TelemetryCar/IMD_Monitor/APPS | I39: TRUE | J39: FALSE | K39: ESP Control Message
A40: =COUNTIF('Main BUS Message'!$A$1:$A$10091,B40) -> 1 | B40: 0x018 | C40: MCUStatusDash | D40: 1000 | E40: 8 | F40: =IF((I40),(E40+3)*(1000/D40)/1000,0) -> 0.011 | G40: Dash | H40: Logger | I40: TRUE | J40: FALSE | K40: MCU Status Message
A41: =COUNTIF('Main BUS Message'!$A$1:$A$10091,B41) -> 0 | B41: 0x0FF | C41: MCUStatusDebug | D41: 1000 | E41: 8 | F41: =IF((I41),(E41+3)*(1000/D41)/1000,0) -> 0 | G41: Debug | H41: Logger | I41: FALSE | J41: FALSE | K41: MCU Status Message
A42: =COUNTIF('Main BUS Message'!$A$1:$A$10091,B42) -> 1 | B42: 0x204 | C42: FLTireTemp1 | D42: 30 | E42: 8 | F42: =IF((I42),(E42+3)*(1000/D42)/1000,0) -> 0.36666667 | G42: FLTireTemp | H42: Screen | I42: TRUE | J42: FALSE | K42: Front Left Tire temperature sensor channels 1-4
A43: =COUNTIF('Main BUS Message'!$A$1:$A$10091,B43) -> 1 | B43: 0x205 | C43: FLTireTemp2 | D43: 30 | E43: 8 | F43: =IF((I43),(E43+3)*(1000/D43)/1000,0) -> 0.36666667 | G43: FLTireTemp | H43: Screen | I43: TRUE | J43: FALSE | K43: Front Left Tire temperature sensor channels 5-8
A44: =COUNTIF('Main BUS Message'!$A$1:$A$10091,B44) -> 1 | B44: 0x206 | C44: FLTireTemp3 | D44: 30 | E44: 8 | F44: =IF((I44),(E44+3)*(1000/D44)/1000,0) -> 0.36666667 | G44: FLTireTemp | H44: Screen | I44: TRUE | J44: FALSE | K44: Front Left Tire temperature sensor channels 9-12
A45: =COUNTIF('Main BUS Message'!$A$1:$A$10091,B45) -> 1 | B45: 0x207 | C45: FLTireTemp4 | D45: 30 | E45: 8 | F45: =IF((I45),(E45+3)*(1000/D45)/1000,0) -> 0.36666667 | G45: FLTireTemp | H45: Screen | I45: TRUE | J45: FALSE | K45: Front Left Tire temperature sensor channels 13-16
A46: =COUNTIF('Main BUS Message'!$A$1:$A$10091,B46) -> 1 | B46: 0x200 | C46: FRTireTemp1 | D46: 30 | E46: 8 | F46: =IF((I46),(E46+3)*(1000/D46)/1000,0) -> 0.36666667 | G46: FRTireTemp | H46: Screen | I46: TRUE | J46: FALSE | K46: Front Right Tire temperature sensor channels 1-4
A47: =COUNTIF('Main BUS Message'!$A$1:$A$10091,B47) -> 1 | B47: 0x201 | C47: FRTireTemp2 | D47: 30 | E47: 8 | F47: =IF((I47),(E47+3)*(1000/D47)/1000,0) -> 0.36666667 | G47: FRTireTemp | H47: Screen | I47: TRUE | J47: FALSE | K47: Front Right Tire temperature sensor channels 5-8
A48: =COUNTIF('Main BUS Message'!$A$1:$A$10091,B48) -> 1 | B48: 0x202 | C48: FRTireTemp3 | D48: 30 | E48: 8 | F48: =IF((I48),(E48+3)*(1000/D48)/1000,0) -> 0.36666667 | G48: FRTireTemp | H48: Screen | I48: TRUE | J48: FALSE | K48: Front Right Tire temperature sensor channels 9-12
A49: =COUNTIF('Main BUS Message'!$A$1:$A$10091,B49) -> 1 | B49: 0x203 | C49: FRTireTemp4 | D49: 30 | E49: 8 | F49: =IF((I49),(E49+3)*(1000/D49)/1000,0) -> 0.36666667 | G49: FRTireTemp | H49: Screen | I49: TRUE | J49: FALSE | K49: Front Right Tire temperature sensor channels 13-16
A50: =COUNTIF('Main BUS Message'!$A$1:$A$10091,B50) -> 1 | B50: 0x013 | C50: MCUStatusIMDMonitor | D50: 1000 | E50: 8 | F50: =IF((I50),(E50+3)*(1000/D50)/1000,0) -> 0.011 | G50: IMD_Monitor | H50: Logger | I50: TRUE | J50: TRUE | K50: MCU Status Message
...

Sheet Main BUS Message
A2: ID | B2: Length (bytes) | C2: start bit | D2: length (bits) | E2: Name | F2: Description | G2: Byte Order | H2: Signed | I2: Gain | J2: Offset | K2: Unit | L2: Min Value | M2: Max Value | N2: Resolution
A3: 0x024 | B3: 2 | C3: 0 | D3: 16 | E3: AC Current SET | F3: READ THE COMMENT Sets the target motor AC Peak current, auto switches to current control mode | G3: MSB First | H3: YES | I3: 0.1 | J3: 0 | K3: Apk | L3: =IF(H3="NO", J3, (-(2^(D3-1))+J3)*I3) -> -3276.8 | M3: =IF(H3="NO",(((2^D3)-1+J3)*I3),(((2^(D3-1))-1+J3)*I3)) -> 3276.7 | N3: =(M3-L3)/(2^D3) -> 0.099998474
C4: 16 | L4: =IF(H4="NO", J4, (-(2^(D4-1))+J4)*I4) -> 0 | M4: =IF(H4="NO",(((2^D4)-1+J4)*I4),(((2^(D4-1))-1+J4)*I4)) -> 0 | N4: =(M4-L4)/(2^D4) -> 0
A6: 0x044 | B6: 2 | C6: 0 | D6: 16 | E6: Target brake current SET | F6: ONLY POSITIVE CURRENTS ARE ACCEPTED Targets the brake current of the motor, resulting in negative torque, relative to the forward direction of the motor. | G6: MSB First | H6: YES | I6: 0.1 | J6: 0 | K6: Apk | L6: =IF(H6="NO", J6, (-(2^(D6-1))+J6)*I6) -> -3276.8 | M6: =IF(H6="NO",(((2^D6)-1+J6)*I6),(((2^(D6-1))-1+J6)*I6)) -> 3276.7 | N6: =(M6-L6)/(2^D6) -> 0.099998474
C7: 16 | L7: =IF(H7="NO", J7, (-(2^(D7-1))+J7)*I7) -> 0 | M7: =IF(H7="NO",(((2^D7)-1+J7)*I7),(((2^(D7-1))-1+J7)*I7)) -> 0 | N7: =(M7-L7)/(2^D7) -> 0
A9: 0x064 | B9: 4 | C9: 0 | D9: 32 | E9: Target ERPM SET | F9: Enable speed control of motor using target ERPM, Sign is direction of spinning, | G9: MSB First | H9: YES | I9: 1 | J9: 0 | K9: ERPM | L9: =IF(H9="NO", J9, (-(2^(D9-1))+J9)*I9) -> -2147483648 | M9: =IF(H9="NO",(((2^D9)-1+J9)*I9),(((2^(D9-1))-1+J9)*I9)) -> 2147483647 | N9: =(M9-L9)/(2^D9) -> 1
C10: 32 | L10: =IF(H10="NO", J10, (-(2^(D10-1))+J10)*I10) -> 0 | M10: =IF(H10="NO",(((2^D10)-1+J10)*I10),(((2^(D10-1))-1+J10)*I10)) -> 0 | N10: =(M10-L10)/(2^D10) -> 0
A12: 0x084 | B12: 2 | C12: 0 | D12: 16 | E12: Target Position SET | F12: Target the desired position of the motor in degrees, hold position of motor | G12: MSB First | H12: YES | I12: 0.1 | J12: 0 | K12: degrees | L12: =IF(H12="NO", J12, (-(2^(D12-1))+J12)*I12) -> -3276.8 | M12: =IF(H12="NO",(((2^D12)-1+J12)*I12),(((2^(D12-1))-1+J12)*I12)) -> 3276.7 | N12: =(M12-L12)/(2^D12) -> 0.099998474
C13: 16 | L13: =IF(H13="NO", J13, (-(2^(D13-1))+J13)*I13) -> 0 | M13: =IF(H13="NO",(((2^D13)-1+J13)*I13),(((2^(D13-1))-1+J13)*I13)) -> 0 | N13: =(M13-L13)/(2^D13) -> 0
A15: 0x0A4 | B15: 2 | C15: 0 | D15: 16 | E15: Target relative AC current SET | F15: Set relative motor AC current between limits using percentages COMMENT! | G15: MSB First | H15: YES | I15: 0.1 | J15: 0 | K15: % | L15: =IF(H15="NO", J15, (-(2^(D15-1))+J15)*I15) -> -3276.8 | M15: =IF(H15="NO",(((2^D15)-1+J15)*I15),(((2^(D15-1))-1+J15)*I15)) -> 3276.7 | N15: =(M15-L15)/(2^D15) -> 0.099998474 | O15: -100 -> 100%
C16: 16 | L16: =IF(H16="NO", J16, (-(2^(D16-1))+J16)*I16) -> 0 | M16: =IF(H16="NO",(((2^D16)-1+J16)*I16),(((2^(D16-1))-1+J16)*I16)) -> 0 | N16: =(M16-L16)/(2^D16) -> 0
A18: 0x0C4 | B18: 2 | C18: 0 | D18: 16 | E18: RelativeBrakeACCurrent | F18: Set relative AC motor brake current between limits using % | G18: MSB First | H18: YES | I18: 0.1 | J18: 0 | K18: % | L18: =IF(H18="NO", J18, (-(2^(D18-1))+J18)*I18) -> -3276.8 | M18: =IF(H18="NO",(((2^D18)-1+J18)*I18),(((2^(D18-1))-1+J18)*I18)) -> 3276.7 | N18: =(M18-L18)/(2^D18) -> 0.099998474 | O18: 0 -> 100%
C19: 16 | L19: =IF(H19="NO", J19, (-(2^(D19-1))+J19)*I19) -> 0 | M19: =IF(H19="NO",(((2^D19)-1+J19)*I19),(((2^(D19-1))-1+J19)*I19)) -> 0 | N19: =(M19-L19)/(2^D19) -> 0
A21: 0x0E4 | B21: 8 | C21: 0 | D21: 1 | E21: Digital Output 1 | F21: Sets the digital output 1 to HIGH (1) or LOW (0) state | G21: MSB First | H21: NO | I21: 1 | J21: 0 | L21: =IF(H21="NO", J21, (-(2^(D21-1))+J21)*I21) -> 0 | M21: =IF(H21="NO",(((2^D21)-1+J21)*I21),(((2^(D21-1))-1+J21)*I21)) -> 1 | N21: =(M21-L21)/(2^D21) -> 0.5
C22: 1 | D22: 1 | E22: Digital Output 2 | F22: Sets the digital output 2 to HIGH (1) or LOW (0) state | G22: MSB First | H22: NO | I22: 1 | J22: 0 | L22: =IF(H22="NO", J22, (-(2^(D22-1))+J22)*I22) -> 0 | M22: =IF(H22="NO",(((2^D22)-1+J22)*I22),(((2^(D22-1))-1+J22)*I22)) -> 1 | N22: =(M22-L22)/(2^D22) -> 0.5
C23: 2 | D23: 1 | E23: Digital Output 3 | F23: Sets the digital output 3 to HIGH (1) or LOW (0) state | G23: MSB First | H23: NO | I23: 1 | J23: 0 | L23: =IF(H23="NO", J23, (-(2^(D23-1))+J23)*I23) -> 0 | M23: =IF(H23="NO",(((2^D23)-1+J23)*I23),(((2^(D23-1))-1+J23)*I23)) -> 1 | N23: =(M23-L23)/(2^D23) -> 0.5
C24: 3 | D24: 1 | E24: Digital Output 4 | F24: Sets the digital output 4 to HIGH (1) or LOW (0) state | G24: MSB First | H24: NO | I24: 1 | J24: 0 | L24: =IF(H24="NO", J24, (-(2^(D24-1))+J24)*I24) -> 0 | M24: =IF(H24="NO",(((2^D24)-1+J24)*I24),(((2^(D24-1))-1+J24)*I24)) -> 1 | N24: =(M24-L24)/(2^D24) -> 0.5
C25: 4 | D25: 60 | E25: RESERVED | F25: The documentation treats this like it doesn't exist | G25: MSB First | H25: YES | L25: =IF(H25="NO", J25, (-(2^(D25-1))+J25)*I25) -> 0 | M25: =IF(H25="NO",(((2^D25)-1+J25)*I25),(((2^(D25-1))-1+J25)*I25)) -> 0 | N25: =(M25-L25)/(2^D25) -> 0
C26: 64 | L26: =IF(H26="NO", J26, (-(2^(D26-1))+J26)*I26) -> 0 | M26: =IF(H26="NO",(((2^D26)-1+J26)*I26),(((2^(D26-1))-1+J26)*I26)) -> 0 | N26: =(M26-L26)/(2^D26) -> 0
A28: 0x104 | B28: 8 | C28: 8 | D28: 16 | E28: Max AC Current SET | F28: Set the maximum allowable drive current on the AC side | G28: MSB First | H28: YES | I28: 0.1 | J28: 0 | K28: Apk | L28: =IF(H28="NO", J28, (-(2^(D28-1))+J28)*I28) -> -3276.8 | M28: =IF(H28="NO",(((2^D28)-1+J28)*I28),(((2^(D28-1))-1+J28)*I28)) -> 3276.7 | N28: =(M28-L28)/(2^D28) -> 0.099998474
C29: 24 | D29: 48 | E29: RESERVED | F29: Not relevant to the command, fill with FF's or use 2-byte DLC | G29: MSB First | H29: YES | L29: =IF(H29="NO", J29, (-(2^(D29-1))+J29)*I29) -> 0 | M29: =IF(H29="NO",(((2^D29)-1+J29)*I29),(((2^(D29-1))-1+J29)*I29)) -> 0 | N29: =(M29-L29)/(2^D29) -> 0
C30: 64 | L30: =IF(H30="NO", J30, (-(2^(D30-1))+J30)*I30) -> 0 | M30: =IF(H30="NO",(((2^D30)-1+J30)*I30),(((2^(D30-1))-1+J30)*I30)) -> 0 | N30: =(M30-L30)/(2^D30) -> 0
A32: 0x124 | B32: 2 | C32: 8 | D32: 16 | E32: Max brake AC current SET | F32: ONLY NEGATIVE CURRENTS ACCEPTEDSets the maximum allowable brake current on the AC side | G32: MSB First | H32: YES | I32: 0.1 | J32: 0 | K32: Apk | L32: =IF(H32="NO", J32, (-(2^(D32-1))+J32)*I32) -> -3276.8 | M32: =IF(H32="NO",(((2^D32)-1+J32)*I32),(((2^(D32-1))-1+J32)*I32)) -> 3276.7 | N32: =(M32-L32)/(2^D32) -> 0.099998474
C33: 16 | L33: =IF(H33="NO", J33, (-(2^(D33-1))+J33)*I33) -> 0 | M33: =IF(H33="NO",(((2^D33)-1+J33)*I33),(((2^(D33-1))-1+J33)*I33)) -> 0 | N33: =(M33-L33)/(2^D33) -> 0
A35: 0x144 | B35: 2 | C35: 8 | D35: 16 | E35: Max DC current SET | F35: Maximum allowable drive current on the DC side, (batt discharge current) | G35: MSB First | H35: YES | I35: 0.1 | J35: 0 | K35: A | L35: =IF(H35="NO", J35, (-(2^(D35-1))+J35)*I35) -> -3276.8 | M35: =IF(H35="NO",(((2^D35)-1+J35)*I35),(((2^(D35-1))-1+J35)*I35)) -> 3276.7 | N35: =(M35-L35)/(2^D35) -> 0.099998474
C36: 24 | L36: =IF(H36="NO", J36, (-(2^(D36-1))+J36)*I36) -> 0 | M36: =IF(H36="NO",(((2^D36)-1+J36)*I36),(((2^(D36-1))-1+J36)*I36)) -> 0 | N36: =(M36-L36)/(2^D36) -> 0
A38: 0x164 | B38: 2 | C38: 8 | D38: 16 | E38: Maximum brake DC current SET | F38: ONLY NEGATIVE CURRENTS ACCEPTED Maximum allowable brake current DC side | G38: MSB First | H38: YES | I38: 0.1 | J38: 0 | K38: % | L38: =IF(H38="NO", J38, (-(2^(D38-1))+J38)*I38) -> -3276.8 | M38: =IF(H38="NO",(((2^D38)-1+J38)*I38),(((2^(D38-1))-1+J38)*I38)) -> 3276.7 | N38: =(M38-L38)/(2^D38) -> 0.099998474
C39: 24 | L39: =IF(H39="NO", J39, (-(2^(D39-1))+J39)*I39) -> 0 | M39: =IF(H39="NO",(((2^D39)-1+J39)*I39),(((2^(D39-1))-1+J39)*I39)) -> 0 | N39: =(M39-L39)/(2^D39) -> 0
A41: 0x184 | B41: 1 | C41: 0 | D41: 1 | E41: Drive enable | F41: Must be sent periodically to be enabled, 1 = enable, 0 = disable | G41: MSB First | H41: NO | I41: 1 | J41: 0 | L41: =IF(H41="NO", J41, (-(2^(D41-1))+J41)*I41) -> 0 | M41: =IF(H41="NO",(((2^D41)-1+J41)*I41),(((2^(D41-1))-1+J41)*I41)) -> 1 | N41: =(M41-L41)/(2^D41) -> 0.5
C42: 1 | D42: 7 | E42: RESERVED | G42: MSB First | L42: =IF(H42="NO", J42, (-(2^(D42-1))+J42)*I42) -> 0 | M42: =IF(H42="NO",(((2^D42)-1+J42)*I42),(((2^(D42-1))-1+J42)*I42)) -> 0 | N42: =(M42-L42)/(2^D42) -> 0
C43: 8 | L43: =IF(H43="NO", J43, (-(2^(D43-1))+J43)*I43) -> 0 | M43: =IF(H43="NO",(((2^D43)-1+J43)*I43),(((2^(D43-1))-1+J43)*I43)) -> 0 | N43: =(M43-L43)/(2^D43) -> 0
A45: 0x010 | B45: 2 | C45: 0 | D45: 1 | E45: BRestart | F45: Restart all MCUs | G45: MSB First | H45: NO | I45: 1 | J45: 0 | L45: =IF(H45="NO", J45, (-(2^(D45-1))+J45)*I45) -> 0 | M45: =IF(H45="NO",(((2^D45)-1+J45)*I45),(((2^(D45-1))-1+J45)*I45)) -> 1 | N45: =(M45-L45)/(2^D45) -> 0.5
C46: =C45+D45 -> 1 | D46: 1 | E46: BClearMinMax | F46: Clear Min/ Max Recorded Values | G46: MSB First | H46: NO | I46: 1 | J46: 0 | L46: =IF(H46="NO", J46, (-(2^(D46-1))+J46)*I46) -> 0 | M46: =IF(H46="NO",(((2^D46)-1+J46)*I46),(((2^(D46-1))-1+J46)*I46)) -> 1 | N46: =(M46-L46)/(2^D46) -> 0.5
C47: =C46+D46 -> 2 | D47: 1 | E47: BClearErrors | F47: Clear Any Latched Values | G47: MSB First | H47: NO | I47: 1 | J47: 0 | L47: =IF(H47="NO", J47, (-(2^(D47-1))+J47)*I47) -> 0 | M47: =IF(H47="NO",(((2^D47)-1+J47)*I47),(((2^(D47-1))-1+J47)*I47)) -> 1 | N47: =(M47-L47)/(2^D47) -> 0.5
C48: =C47+D47 -> 3 | D48: =16-3 -> 13 | E48: Spare | G48: MSB First | H48: NO | J48: 0 | L48: =IF(H48="NO", J48, (-(2^(D48-1))+J48)*I48) -> 0 | M48: =IF(H48="NO",(((2^D48)-1+J48)*I48),(((2^(D48-1))-1+J48)*I48)) -> 0 | N48: =(M48-L48)/(2^D48) -> 0
C49: =C48+D48 -> 16 | J49: 0 | L49: =IF(H49="NO", J49, (-(2^(D49-1))+J49)*I49) -> 0 | M49: =IF(H49="NO",(((2^D49)-1+J49)*I49),(((2^(D49-1))-1+J49)*I49)) -> 0 | N49: =(M49-L49)/(2^D49) -> 0
A51: 0x404 | B51: 8 | C51: 0 | D51: 32 | E51: ERPM | F51: ERPM = Motor RPM * number of motor pole pairs | G51: MSB First | H51: YES | I51: 1 | J51: 0 | K51: ERPM | L51: =IF(H51="NO", J51, (-(2^(D51-1))+J51)*I51) -> -2147483648 | M51: =IF(H51="NO",(((2^D51)-1+J51)*I51),(((2^(D51-1))-1+J51)*I51)) -> 2147483647 | N51: =(M51-L51)/(2^D51) -> 1
C52: 32 | D52: 16 | E52: Duty Cycle | F52: Controller Duty Cycle, +ve = running -ve = regenerating | G52: MSB First | H52: YES | I52: 0.1 | J52: 0 | K52: % | L52: =IF(H52="NO", J52, (-(2^(D52-1))+J52)*I52) -> -3276.8 | M52: =IF(H52="NO",(((2^D52)-1+J52)*I52),(((2^(D52-1))-1+J52)*I52)) -> 3276.7 | N52: =(M52-L52)/(2^D52) -> 0.099998474
C53: 48 | D53: =64-C53 -> 16 | E53: Input Voltage | F53: Input voltage DC voltage | G53: MSB First | H53: YES | I53: 1 | J53: 0 | K53: V | L53: =IF(H53="NO", J53, (-(2^(D53-1))+J53)*I53) -> -32768 | M53: =IF(H53="NO",(((2^D53)-1+J53)*I53),(((2^(D53-1))-1+J53)*I53)) -> 32767 | N53: =(M53-L53)/(2^D53) -> 0.99998474
C54: 64 | L54: =IF(H54="NO", J54, (-(2^(D54-1))+J54)*I54) -> 0 | N54: =(M54-L54)/(2^D54) -> 0
...
